Workbook

Sheet Исходные данные
B1: Номер в реестре | C1: Id пакета | D1: FIO | E1: Наименование работодателя | F1: ИНН работодателя | G1: Должность | H1: Наименование организации проводившей обучение | I1: ИНН организации проводившей обучение | J1: Номер протокола | K1: Программа обучения | L1: Дата проверки знаний | M1: Результат | N1: Дата внесения в реестр | O1: Аннулировано | P1: Дата аннулирования | Q1: Источник отправки | R1: Избыток / недостаток | S1: Основание недостатка/избытка
B2: 6485895 | C2: 587412 | D2: работник 1 | E2: ООО "Амур золото". Подразделение: горно-обогатительный комплекс "Юбилейный" | F2: 2708001686 | G2: Директор | H2: Автономная некоммерческая организация дополнительного профессионального образования и сертификации "Перспектива" | I2: 2722126782 | J2: ОТ-А 0035-23 | K2: Общие вопросы охраны труда и функционирования системы управления охраной труда | L2: 26.05.2023 | M2: Успешно | N2: 01.06.2023 | Q2: Пользовательский интерфейс | R2: Нет отклонения | S2: ПП РФ № 2464, п. 53 подп. «а»: руководителю организации программа 46а требуется.
B3: 6485896 | C3: 587412 | D3: работник 2 | E3: ООО "Амур золото". Подразделение: горно-обогатительный комплекс "Юбилейный" | F3: 2708001686 | G3: Заместитель директора горно-обогатительного комплекса по производству | H3: Автономная некоммерческая организация дополнительного профессионального образования и сертификации "Перспектива" | I3: 2722126782 | J3: ОТ-А 0035-23 | K3: Общие вопросы охраны труда и функционирования системы управления охраной труда | L3: 26.05.2023 | M3: Успешно | N3: 01.06.2023 | Q3: Пользовательский интерфейс | R3: Нет отклонения | S3: ПП РФ № 2464, п. 53 подп. «б»: заместителю руководителя структурного подразделения программы 46а и 46б требуются.
B4: 6485897 | C4: 587412 | D4: работник 3 | E4: ООО "Амур золото". Подразделение: горно-обогатительный комплекс "Юбилейный" | F4: 2708001686 | G4: Инженер по промышленной безопасности и охране труда | H4: Автономная некоммерческая организация дополнительного профессионального образования и сертификации "Перспектива" | I4: 2722126782 | J4: ОТ-А 0035-23 | K4: Общие вопросы охраны труда и функционирования системы управления охраной труда | L4: 26.05.2023 | M4: Успешно | N4: 01.06.2023 | Q4: Пользовательский интерфейс | R4: Нет отклонения | S4: ПП РФ № 2464, п. 53 подп. «г»: специалисту по охране труда программа 46а требуется.
B5: 6485898 | C5: 587412 | D5: работник 4 | E5: ООО "Амур золото". Подразделение: горно-обогатительный комплекс "Юбилейный" | F5: 2708001686 | G5: Инженер по промышленной безопасности и охране труда | H5: Автономная некоммерческая организация дополнительного профессионального образования и сертификации "Перспектива" | I5: 2722126782 | J5: ОТ-А 0035-23 | K5: Общие вопросы охраны труда и функционирования системы управления охраной труда | L5: 26.05.2023 | M5: Успешно | N5: 01.06.2023 | Q5: Пользовательский интерфейс | R5: Нет отклонения | S5: ПП РФ № 2464, п. 53 подп. «г»: специалисту по охране труда программа 46а требуется.
B6: 6485899 | C6: 587412 | D6: работник 5 | E6: ООО "Амур золото". Подразделение: горно-обогатительный комплекс "Юбилейный" | F6: 2708001686 | G6: Механик по ремонту самоходного транспорта | H6: Автономная некоммерческая организация дополнительного профессионального образования и сертификации "Перспектива" | I6: 2722126782 | J6: ОТ-А 0035-23 | K6: Общие вопросы охраны труда и функционирования системы управления охраной труда | L6: 26.05.2023 | M6: Успешно | N6: 01.06.2023 | Q6: Пользовательский интерфейс | R6: Избыток обучения | S6: ПП РФ № 2464, п. 53 подп. «в»: специалисту программа 46а не требуется, установлена программа 46б.
B7: 6485900 | C7: 587412 | D7: работник 6 | E7: ООО "Амур золото". Подразделение: горно-обогатительный комплекс "Юбилейный" | F7: 2708001686 | G7: Заместитель начальника участка по буровзрывным работам | H7: Автономная некоммерческая организация дополнительного профессионального образования и сертификации "Перспектива" | I7: 2722126782 | J7: ОТ-А 0035-23 | K7: Общие вопросы охраны труда и функционирования системы управления охраной труда | L7: 26.05.2023 | M7: Успешно | N7: 01.06.2023 | Q7: Пользовательский интерфейс | R7: Нет отклонения | S7: ПП РФ № 2464, п. 53 подп. «б»: заместителю руководителя структурного подразделения программы 46а и 46б требуются.
B8: 6485901 | C8: 587412 | D8: работник 7 | E8: ООО "Амур золото". Подразделение: горно-обогатительный комплекс "Юбилейный" | F8: 2708001686 | G8: Главный технолог | H8: Автономная некоммерческая организация дополнительного профессионального образования и сертификации "Перспектива" | I8: 2722126782 | J8: ОТ-А 0035-23 | K8: Общие вопросы охраны труда и функционирования системы управления охраной труда | L8: 26.05.2023 | M8: Успешно | N8: 01.06.2023 | Q8: Пользовательский интерфейс | R8: Избыток обучения | S8: ПП РФ № 2464, п. 53 подп. «в»: должность не названа руководителем структурного подразделения, специалисту программа 46а не требуется.
B9: 6485902 | C9: 587412 | D9: работник 8 | E9: ООО "Амур золото". Подразделение: горно-обогатительный комплекс "Юбилейный" | F9: 2708001686 | G9: Начальник золотоизвлекательной фабрики | H9: Автономная некоммерческая организация дополнительного профессионального образования и сертификации "Перспектива" | I9: 2722126782 | J9: ОТ-А 0035-23 | K9: Общие вопросы охраны труда и функционирования системы управления охраной труда | L9: 26.05.2023 | M9: Успешно | N9: 01.06.2023 | Q9: Пользовательский интерфейс | R9: Нет отклонения | S9: ПП РФ № 2464, п. 53 подп. «б»: руководителю структурного подразделения программы 46а и 46б требуются.
B10: 6485903 | C10: 587412 | D10: работник 9 | E10: ООО "Амур золото". Подразделение: горно-обогатительный комплекс "Юбилейный" | F10: 2708001686 | G10: Заместитель начальника золотоизвлекательной фабрики | H10: Автономная некоммерческая организация дополнительного профессионального образования и сертификации "Перспектива" | I10: 2722126782 | J10: ОТ-А 0035-23 | K10: Общие вопросы охраны труда и функционирования системы управления охраной труда | L10: 26.05.2023 | M10: Успешно | N10: 01.06.2023 | Q10: Пользовательский интерфейс | R10: Нет отклонения | S10: ПП РФ № 2464, п. 53 подп. «б»: заместителю руководителя структурного подразделения программы 46а и 46б требуются.
B11: 6485904 | C11: 587412 | D11: работник 10 | E11: ООО "Амур золото". Подразделение: горно-обогатительный комплекс "Юбилейный" | F11: 2708001686 | G11: Главный энергетик | H11: Автономная некоммерческая организация дополнительного профессионального образования и сертификации "Перспектива" | I11: 2722126782 | J11: ОТ-А 0035-23 | K11: Общие вопросы охраны труда и функционирования системы управления охраной труда | L11: 26.05.2023 | M11: Успешно | N11: 01.06.2023 | Q11: Пользовательский интерфейс | R11: Избыток обучения | S11: ПП РФ № 2464, п. 53 подп. «в»: должность не названа руководителем структурного подразделения, специалисту программа 46а не требуется.
B12: 6485905 | C12: 587412 | D12: работник 11 | E12: ООО "Амур золото". Подразделение: горно-обогатительный комплекс "Юбилейный" | F12: 2708001686 | G12: Теплотехник | H12: Автономная некоммерческая организация дополнительного профессионального образования и сертификации "Перспектива" | I12: 2722126782 | J12: ОТ-А 0035-23 | K12: Общие вопросы охраны труда и функционирования системы управления охраной труда | L12: 26.05.2023 | M12: Успешно | N12: 01.06.2023 | Q12: Пользовательский интерфейс | R12: Избыток обучения | S12: ПП РФ № 2464, п. 53 подп. «в»: специалисту программа 46а не требуется, установлена программа 46б.
B13: 6485906 | C13: 587412 | D13: работник 12 | E13: ООО "Амур золото". Подразделение: горно-обогатительный комплекс "Юбилейный" | F13: 2708001686 | G13: Электромеханик подземного горного участка | H13: Автономная некоммерческая организация дополнительного профессионального образования и сертификации "Перспектива" | I13: 2722126782 | J13: ОТ-А 0035-23 | K13: Общие вопросы охраны труда и функционирования системы управления охраной труда | L13: 26.05.2023 | M13: Успешно | N13: 01.06.2023 | Q13: Пользовательский интерфейс | R13: Избыток обучения | S13: ПП РФ № 2464, п. 53 подп. «в»: специалисту программа 46а не требуется, установлена программа 46б.
... B15: 6485908 | C15: 587412 | D15: работник 14 | E15: ООО "Амур золото". Подразделение: горно-обогатительный комплекс "Юбилейный" | F15: 2708001686 | G15: Начальник автотранспортного цеха | H15: Автономная некоммерческая организация дополнительного профессионального образования и сертификации "Перспектива" | I15: 2722126782 | J15: ОТ-А 0035-23 | K15: Общие вопросы охраны труда и функционирования системы управления охраной труда | L15: 26.05.2023 | M15: Успешно | N15: 01.06.2023 | Q15: Пользовательский интерфейс | R15: Нет отклонения | S15: ПП РФ № 2464, п. 53 подп. «б»: руководителю структурного подразделения программы 46а и 46б требуются.
B16: 6485909 | C16: 587412 | D16: работник 1 | E16: ООО "Амур золото". Подразделение: горно-обогатительный комплекс "Юбилейный" | F16: 2708001686 | G16: Директор | H16: Автономная некоммерческая организация дополнительного профессионального образования и сертификации "Перспектива" | I16: 2722126782 | J16: ОТ-Б 0033-23 | K16: Безопасные методы и приемы выполнения работ при воздействии вредных и (или) опасных производственных факторов, источников опасности, идентифицированных в рамках специальной оценки условий труда и оценки профессиональных рисков | L16: 26.05.2023 | M16: Успешно | N16: 01.06.2023 | Q16: Пользовательский интерфейс
B17: 6485910 | C17: 587412 | D17: работник 2 | E17: ООО "Амур золото". Подразделение: горно-обогатительный комплекс "Юбилейный" | F17: 2708001686 | G17: Заместитель директора горно-обогатительного комплекса по производству | H17: Автономная некоммерческая организация дополнительного профессионального образования и сертификации "Перспектива" | I17: 2722126782 | J17: ОТ-Б 0033-23 | K17: Безопасные методы и приемы выполнения работ при воздействии вредных и (или) опасных производственных факторов, источников опасности, идентифицированных в рамках специальной оценки условий труда и оценки профессиональных рисков | L17: 26.05.2023 | M17: Успешно | N17: 01.06.2023 | Q17: Пользовательский интерфейс
B18: 6485911 | C18: 587412 | D18: работник 3 | E18: ООО "Амур золото". Подразделение: горно-обогатительный комплекс "Юбилейный" | F18: 2708001686 | G18: Инженер по промышленной безопасности и охране труда | H18: Автономная некоммерческая организация дополнительного профессионального образования и сертификации "Перспектива" | I18: 2722126782 | J18: ОТ-Б 0033-23 | K18: Безопасные методы и приемы выполнения работ при воздействии вредных и (или) опасных производственных факторов, источников опасности, идентифицированных в рамках специальной оценки условий труда и оценки профессиональных рисков | L18: 26.05.2023 | M18: Успешно | N18: 01.06.2023 | Q18: Пользовательский интерфейс
B19: 6485912 | C19: 587412 | D19: работник 4 | E19: ООО "Амур золото". Подразделение: горно-обогатительный комплекс "Юбилейный" | F19: 2708001686 | G19: Инженер по промышленной безопасности и охране труда | H19: Автономная некоммерческая организация дополнительного профессионального образования и сертификации "Перспектива" | I19: 2722126782 | J19: ОТ-Б 0033-23 | K19: Безопасные методы и приемы выполнения работ при воздействии вредных и (или) опасных производственных факторов, источников опасности, идентифицированных в рамках специальной оценки условий труда и оценки профессиональных рисков | L19: 26.05.2023 | M19: Успешно | N19: 01.06.2023 | Q19: Пользовательский интерфейс
B20: 6485913 | C20: 587412 | D20: работник 5 | E20: ООО "Амур золото". Подразделение: горно-обогатительный комплекс "Юбилейный" | F20: 2708001686 | G20: Механик по ремонту самоходного транспорта | H20: Автономная некоммерческая организация дополнительного профессионального образования и сертификации "Перспектива" | I20: 2722126782 | J20: ОТ-Б 0033-23 | K20: Безопасные методы и приемы выполнения работ при воздействии вредных и (или) опасных производственных факторов, источников опасности, идентифицированных в рамках специальной оценки условий труда и оценки профессиональных рисков | L20: 26.05.2023 | M20: Успешно | N20: 01.06.2023 | Q20: Пользовательский интерфейс
B21: 6485914 | C21: 587412 | D21: работник 6 | E21: ООО "Амур золото". Подразделение: горно-обогатительный комплекс "Юбилейный" | F21: 2708001686 | G21: Заместитель начальника участка по буровзрывным работам | H21: Автономная некоммерческая организация дополнительного профессионального образования и сертификации "Перспектива" | I21: 2722126782 | J21: ОТ-Б 0033-23 | K21: Безопасные методы и приемы выполнения работ при воздействии вредных и (или) опасных производственных факторов, источников опасности, идентифицированных в рамках специальной оценки условий труда и оценки профессиональных рисков | L21: 26.05.2023 | M21: Успешно | N21: 01.06.2023 | Q21: Пользовательский интерфейс
B22: 6485915 | C22: 587412 | D22: работник 7 | E22: ООО "Амур золото". Подразделение: горно-обогатительный комплекс "Юбилейный" | F22: 2708001686 | G22: Главный технолог | H22: Автономная некоммерческая организация дополнительного профессионального образования и сертификации "Перспектива" | I22: 2722126782 | J22: ОТ-Б 0033-23 | K22: Безопасные методы и приемы выполнения работ при воздействии вредных и (или) опасных производственных факторов, источников опасности, идентифицированных в рамках специальной оценки условий труда и оценки профессиональных рисков | L22: 26.05.2023 | M22: Успешно | N22: 01.06.2023 | Q22: Пользовательский интерфейс
B23: 6485916 | C23: 587412 | D23: работник 8 | E23: ООО "Амур золото". Подразделение: горно-обогатительный комплекс "Юбилейный" | F23: 2708001686 | G23: Начальник золотоизвлекательной фабрики | H23: Автономная некоммерческая организация дополнительного профессионального образования и сертификации "Перспектива" | I23: 2722126782 | J23: ОТ-Б 0033-23 | K23: Безопасные методы и приемы выполнения работ при воздействии вредных и (или) опасных производственных факторов, источников опасности, идентифицированных в рамках специальной оценки условий труда и оценки профессиональных рисков | L23: 26.05.2023 | M23: Успешно | N23: 01.06.2023 | Q23: Пользовательский интерфейс
B24: 6485917 | C24: 587412 | D24: работник 9 | E24: ООО "Амур золото". Подразделение: горно-обогатительный комплекс "Юбилейный" | F24: 2708001686 | G24: Заместитель начальника золотоизвлекательной фабрики | H24: Автономная некоммерческая организация дополнительного профессионального образования и сертификации "Перспектива" | I24: 2722126782 | J24: ОТ-Б 0033-23 | K24: Безопасные методы и приемы выполнения работ при воздействии вредных и (или) опасных производственных факторов, источников опасности, идентифицированных в рамках специальной оценки условий труда и оценки профессиональных рисков | L24: 26.05.2023 | M24: Успешно | N24: 01.06.2023 | Q24: Пользовательский интерфейс
B25: 6485918 | C25: 587412 | D25: работник 10 | E25: ООО "Амур золото". Подразделение: горно-обогатительный комплекс "Юбилейный" | F25: 2708001686 | G25: Главный энергетик | H25: Автономная некоммерческая организация дополнительного профессионального образования и сертификации "Перспектива" | I25: 2722126782 | J25: ОТ-Б 0033-23 | K25: Безопасные методы и приемы выполнения работ при воздействии вредных и (или) опасных производственных факторов, источников опасности, идентифицированных в рамках специальной оценки условий труда и оценки профессиональных рисков | L25: 26.05.2023 | M25: Успешно | N25: 01.06.2023 | Q25: Пользовательский интерфейс
B26: 6485919 | C26: 587412 | D26: работник 11 | E26: ООО "Амур золото". Подразделение: горно-обогатительный комплекс "Юбилейный" | F26: 2708001686 | G26: Теплотехник | H26: Автономная некоммерческая организация дополнительного профессионального образования и сертификации "Перспектива" | I26: 2722126782 | J26: ОТ-Б 0033-23 | K26: Безопасные методы и приемы выполнения работ при воздействии вредных и (или) опасных производственных факторов, источников опасности, идентифицированных в рамках специальной оценки условий труда и оценки профессиональных рисков | L26: 26.05.2023 | M26: Успешно | N26: 01.06.2023 | Q26: Пользовательский интерфейс
B27: 6485920 | C27: 587412 | D27: работник 12 | E27: ООО "Амур золото". Подразделение: горно-обогатительный комплекс "Юбилейный" | F27: 2708001686 | G27: Электромеханик подземного горного участка | H27: Автономная некоммерческая организация дополнительного профессионального образования и сертификации "Перспектива" | I27: 2722126782 | J27: ОТ-Б 0033-23 | K27: Безопасные методы и приемы выполнения работ при воздействии вредных и (или) опасных производственных факторов, источников опасности, идентифицированных в рамках специальной оценки условий труда и оценки профессиональных рисков | L27: 26.05.2023 | M27: Успешно | N27: 01.06.2023 | Q27: Пользовательский интерфейс
... B1669: 90580099 | C1669: 6934388 | D1669: работник 32 | E1669: ОБЩЕСТВО С ОГРАНИЧЕННОЙ ОТВЕТСТВЕННОСТЬЮ "АМУР ЗОЛОТО" | F1669: 2708001686 | G1669: Электромонтер по ремонту и обслуживанию электрооборудования | H1669: ООО "Амур Золото" | I1669: 2708001686 | J1669: ОТ № ЮГОК ЗИОФ 24-38 | K1669: Безопасные методы и приемы выполнения работ при воздействии вредных и (или) опасных производственных факторов, источников опасности, идентифицированных в рамках специальной оценки условий труда и оценки профессиональных рисков | L1669: 25.11.2024 | M1669: Успешно | N1669: 02.12.2024 | Q1669: Пользовательский интерфейс
B1670: 96539060 | C1670: 7135797 | D1670: работник 94 | E1670: ОБЩЕСТВО С ОГРАНИЧЕННОЙ ОТВЕТСТВЕННОСТЬЮ "АМУР ЗОЛОТО" | F1670: 2708001686 | G1670: Горнорабочий на геологических работах | H1670: ООО "Амур Золото" | I1670: 2708001686 | J1670: ОТ № ЮГОК ГМО 24-05 | K1670: Использование (применение) средств индивидуальной защиты | L1670: 10.12.2024 | M1670: Успешно | N1670: 28.12.2024
B1671: 96539061 | C1671: 7135797 | D1671: работник 94 | E1671: ОБЩЕСТВО С ОГРАНИЧЕННОЙ ОТВЕТСТВЕННОСТЬЮ "АМУР ЗОЛОТО" | F1671: 2708001686 | G1671: Горнорабочий на геологических работах | H1671: ООО "Амур Золото" | I1671: 2708001686 | J1671: ОТ № ЮГОК ГМО 24-05 | K1671: Безопасные методы и приемы выполнения работ при воздействии вредных и (или) опасных производственных факторов, источников опасности, идентифицированных в рамках специальной оценки условий труда и оценки профессиональных рисков | L1671: 10.12.2024 | M1671: Успешно | N1671: 28.12.2024
B1672: 96539062 | C1672: 7135797 | D1672: работник 506 | E1672: ОБЩЕСТВО С ОГРАНИЧЕННОЙ ОТВЕТСТВЕННОСТЬЮ "АМУР ЗОЛОТО" | F1672: 2708001686 | G1672: Филтровальщик | H1672: ООО "Амур Золото" | I1672: 2708001686 | J1672: ОТ № ЮГОК ЗИОФ 24-39 | K1672: Использование (применение) средств индивидуальной защиты | L1672: 10.12.2024 | M1672: Успешно | N1672: 28.12.2024
B1673: 96539063 | C1673: 7135797 | D1673: работник 506 | E1673: ОБЩЕСТВО С ОГРАНИЧЕННОЙ ОТВЕТСТВЕННОСТЬЮ "АМУР ЗОЛОТО" | F1673: 2708001686 | G1673: Филтровальщик | H1673: ООО "Амур Золото" | I1673: 2708001686 | J1673: ОТ № ЮГОК ЗИОФ 24-39 | K1673: Безопасные методы и приемы выполнения работ при воздействии вредных и (или) опасных производственных факторов, источников опасности, идентифицированных в рамках специальной оценки условий труда и оценки профессиональных рисков | L1673: 10.12.2024 | M1673: Успешно | N1673: 28.12.2024
B1674: 96539064 | C1674: 7135797 | D1674: работник 23 | E1674: ОБЩЕСТВО С ОГРАНИЧЕННОЙ ОТВЕТСТВЕННОСТЬЮ "АМУР ЗОЛОТО" | F1674: 2708001686 | G1674: Слесарь-ремонтник | H1674: ООО "Амур Золото" | I1674: 2708001686 | J1674: ОТ № ЮГОК ЗИОФ 24-40 | K1674: Безопасные методы и приемы выполнения работ при размещении, монтаже, техническом обслуживании и ремонте технологического оборудования (включая технологическое оборудование) | L1674: 10.12.2024 | M1674: Успешно | N1674: 28.12.2024
B1675: 96539065 | C1675: 7135797 | D1675: работник 23 | E1675: ОБЩЕСТВО С ОГРАНИЧЕННОЙ ОТВЕТСТВЕННОСТЬЮ "АМУР ЗОЛОТО" | F1675: 2708001686 | G1675: Слесарь-ремонтник | H1675: ООО "Амур Золото" | I1675: 2708001686 | J1675: ОТ № ЮГОК ЗИОФ 24-40 | K1675: Безопасные методы и приемы выполнения работ на высоте | L1675: 10.12.2024 | M1675: Успешно | N1675: 28.12.2024
B1676: 96539066 | C1676: 7135797 | D1676: работник 23 | E1676: ОБЩЕСТВО С ОГРАНИЧЕННОЙ ОТВЕТСТВЕННОСТЬЮ "АМУР ЗОЛОТО" | F1676: 2708001686 | G1676: Слесарь-ремонтник | H1676: ООО "Амур Золото" | I1676: 2708001686 | J1676: ОТ № ЮГОК ЗИОФ 24-40 | K1676: Безопасные методы и приемы выполнения работ в ограниченных и замкнутых пространствах (ОЗП) | L1676: 10.12.2024 | M1676: Успешно | N1676: 28.12.2024
B1677: 96539067 | C1677: 7135797 | D1677: работник 23 | E1677: ОБЩЕСТВО С ОГРАНИЧЕННОЙ ОТВЕТСТВЕННОСТЬЮ "АМУР ЗОЛОТО" | F1677: 2708001686 | G1677: Слесарь-ремонтник | H1677: ООО "Амур Золото" | I1677: 2708001686 | J1677: ОТ № ЮГОК ЗИОФ 24-40 | K1677: Безопасные методы и приемы выполнения огневых работ | L1677: 10.12.2024 | M1677: Успешно | N1677: 28.12.2024
B1678: 96539068 | C1678: 7135797 | D1678: работник 23 | E1678: ОБЩЕСТВО С ОГРАНИЧЕННОЙ ОТВЕТСТВЕННОСТЬЮ "АМУР ЗОЛОТО" | F1678: 2708001686 | G1678: Слесарь-ремонтник | H1678: ООО "Амур Золото" | I1678: 2708001686 | J1678: ОТ № ЮГОК ЗИОФ 24-40 | K1678: Безопасные методы и приемы выполнения работ, связанные с эксплуатацией подъемных сооружений | L1678: 10.12.2024 | M1678: Успешно | N1678: 28.12.2024
B1679: 96539069 | C1679: 7135797 | D1679: работник 23 | E1679: ОБЩЕСТВО С ОГРАНИЧЕННОЙ ОТВЕТСТВЕННОСТЬЮ "АМУР ЗОЛОТО" | F1679: 2708001686 | G1679: Слесарь-ремонтник | H1679: ООО "Амур Золото" | I1679: 2708001686 | J1679: ОТ № ЮГОК ЗИОФ 24-40 | K1679: Безопасные методы и приемы выполнения работ, связанные с эксплуатацией сосудов, работающих под избыточным давлением | L1679: 10.12.2024 | M1679: Успешно | N1679: 28.12.2024
B1680: 96539070 | C1680: 7135797 | D1680: работник 24 | E1680: ОБЩЕСТВО С ОГРАНИЧЕННОЙ ОТВЕТСТВЕННОСТЬЮ "АМУР ЗОЛОТО" | F1680: 2708001686 | G1680: Слесарь-ремонтник | H1680: ООО "Амур Золото" | I1680: 2708001686 | J1680: ОТ № ЮГОК ЗИОФ 24-40 | K1680: Безопасные методы и приемы выполнения работ при размещении, монтаже, техническом обслуживании и ремонте технологического оборудования (включая технологическое оборудование) | L1680: 10.12.2024 | M1680: Успешно | N1680: 28.12.2024
B1681: 96539071 | C1681: 7135797 | D1681: работник 24 | E1681: ОБЩЕСТВО С ОГРАНИЧЕННОЙ ОТВЕТСТВЕННОСТЬЮ "АМУР ЗОЛОТО" | F1681: 2708001686 | G1681: Слесарь-ремонтник | H1681: ООО "Амур Золото" | I1681: 2708001686 | J1681: ОТ № ЮГОК ЗИОФ 24-40 | K1681: Безопасные методы и приемы выполнения работ на высоте | L1681: 10.12.2024 | M1681: Успешно | N1681: 28.12.2024
... B1801: 99714083 | C1801: 7576385 | D1801: работник 509 | E1801: ОБЩЕСТВО С ОГРАНИЧЕННОЙ ОТВЕТСТВЕННОСТЬЮ "АМУР ЗОЛОТО" | F1801: 2708001686 | G1801: Горнорабочиий на маркшейдерских работах | H1801: ООО "Амур Золото" | I1801: 2708001686 | J1801: ОТ №ЮГОК ГМО 25-01 | K1801: Безопасные методы и приемы выполнения работ при воздействии вредных и (или) опасных производственных факторов, источников опасности, идентифицированных в рамках специальной оценки условий труда и оценки профессиональных рисков | L1801: 22.01.2025 | M1801: Успешно | N1801: 24.01.2025
...

Sheet Сводная
A1: FIO | B1: Должность | C1: Наименование работодателя | D1: ИНН работодателя | E1: Наименование организации проводившей обучение | F1: ИНН организации проводившей обучение | G1: Результат | H1: Аннулировано | I1: Дата аннулирования | J1: Источник отправки | K1: Записей в реестре | L1: 46а. Общие вопросы охраны труда | M1: 46б. Безопасные методы при вредных и опасных факторах | N1: 46в. Работы на высоте | O1: 46в. Огневые работы | P1: 46в. Работы в ОЗП | Q1: 46в. Подъемные сооружения | R1: 46в. Сосуды под давлением | S1: 46в. Технологическое оборудование | T1: 46в. Электроустановки | U1: 46в. Строительные работы | V1: 46в. Ремонт, монтаж и демонтаж зданий | W1: 46в. Земляные работы | X1: Первая помощь пострадавшим | Y1: Применение СИЗ
A2: работник 216 | B2: Водитель автомобиля (категория Д) | C2: ОБЩЕСТВО С ОГРАНИЧЕННОЙ ОТВЕТСТВЕННОСТЬЮ "АМУР ЗОЛОТО" | D2: 2708001686 | E2: ООО "Амур Золото" | F2: 2708001686 | G2: Успешно | J2: Пользовательский интерфейс | K2: 3 | M2: + | X2: + | Y2: +
A3: работник 464 | B3: Водитель автомобиля (категория D) | C3: ОБЩЕСТВО С ОГРАНИЧЕННОЙ ОТВЕТСТВЕННОСТЬЮ "АМУР ЗОЛОТО" | D3: 2708001686 | E3: ООО "Амур Золото" | F3: 2708001686 | G3: Успешно | J3: Пользовательский интерфейс | K3: 2 | M3: + | Y3: +
A4: работник 406 | B4: Водитель автомобиля (категория С) / Водитель автомобиля кат. С | C4: ОБЩЕСТВО С ОГРАНИЧЕННОЙ ОТВЕТСТВЕННОСТЬЮ "АМУР ЗОЛОТО" | D4: 2708001686 | E4: ООО "Амур Золото" | F4: 2708001686 | G4: Успешно | J4: Пользовательский интерфейс | K4: 5 | M4: + | X4: + | Y4: +
A5: работник 146 | B5: Проходчик (с исполнением обязанностей взрывника) | C5: ОБЩЕСТВО С ОГРАНИЧЕННОЙ ОТВЕТСТВЕННОСТЬЮ "АМУР ЗОЛОТО" | D5: 2708001686 | E5: ООО "Амур Золото" | F5: 2708001686 | G5: Успешно | J5: Пользовательский интерфейс | K5: 5 | M5: + | X5: + | Y5: +
A6: работник 606 | B6: Лаборант химического анализа / Кухонный рабочий | C6: ОБЩЕСТВО С ОГРАНИЧЕННОЙ ОТВЕТСТВЕННОСТЬЮ "АМУР ЗОЛОТО" | D6: 2708001686 | E6: ООО "Амур Золото" | F6: 2708001686 | G6: Успешно | J6: Пользовательский интерфейс | K6: 5 | M6: + | X6: + | Y6: +
A7: работник 32 | B7: Электромонтер по ремонту и обслуживанию электрооборудованию / Электромонтер по ремонту и обслуживанию электрооборудования / Проходчик (с исполнением обязанностей взрывника) / Электромантер | C7: ОБЩЕСТВО С ОГРАНИЧЕННОЙ ОТВЕТСТВЕННОСТЬЮ "АМУР ЗОЛОТО" | D7: 2708001686 | E7: ООО "Амур Золото" | F7: 2708001686 | G7: Успешно | J7: Пользовательский интерфейс | K7: 14 | M7: + | N7: + | O7: + | P7: + | Q7: + | R7: + | S7: + | T7: + | Y7: +
A8: работник 306 | B8: Машинист самоходной буровой установки | C8: ОБЩЕСТВО С ОГРАНИЧЕННОЙ ОТВЕТСТВЕННОСТЬЮ "АМУР ЗОЛОТО" | D8: 2708001686 | E8: ООО "Амур Золото" | F8: 2708001686 | G8: Успешно | J8: Пользовательский интерфейс | K8: 3 | M8: + | X8: + | Y8: +
A9: работник 572 | B9: Электромонтер по ремонту и обслуживанию электрооборудования | C9: ОБЩЕСТВО С ОГРАНИЧЕННОЙ ОТВЕТСТВЕННОСТЬЮ "АМУР ЗОЛОТО" | D9: 2708001686 | E9: ООО "Амур Золото" | F9: 2708001686 | G9: Успешно | K9: 2 | M9: + | Y9: +
A10: работник 126 | B10: Дробильщик / Дробильщики | C10: ОБЩЕСТВО С ОГРАНИЧЕННОЙ ОТВЕТСТВЕННОСТЬЮ "АМУР ЗОЛОТО" | D10: 2708001686 | E10: ООО "Амур Золото" | F10: 2708001686 | G10: Успешно | J10: Пользовательский интерфейс | K10: 6 | M10: + | X10: + | Y10: +
A11: работник 78 | B11: Электрогазосварщик (занятый на резке и ручной сварке) / Электрогазосварщик / Сварщик | C11: ОБЩЕСТВО С ОГРАНИЧЕННОЙ ОТВЕТСТВЕННОСТЬЮ "АМУР ЗОЛОТО" | D11: 2708001686 | E11: ООО "Амур Золото" | F11: 2708001686 | G11: Успешно | J11: Пользовательский интерфейс | K11: 15 | M11: + | N11: + | O11: + | U11: + | V11: + | X11: + | Y11: +
A12: работник 666 | B12: Электрослесарь (слесарь) дежурный и по ремонту оборудования | C12: ОБЩЕСТВО С ОГРАНИЧЕННОЙ ОТВЕТСТВЕННОСТЬЮ "АМУР ЗОЛОТО" | D12: 2708001686 | E12: ООО "Амур Золото" | F12: 2708001686 | G12: Успешно | J12: Пользовательский интерфейс | K12: 5 | M12: + | X12: + | Y12: +
A13: работник 825 | B13: Уборщик производственных и служебных помещений | C13: ОБЩЕСТВО С ОГРАНИЧЕННОЙ ОТВЕТСТВЕННОСТЬЮ "АМУР ЗОЛОТО" | D13: 2708001686 | E13: ООО "Амур Золото" | F13: 2708001686 | G13: Успешно | J13: Пользовательский интерфейс | K13: 2 | M13: + | Y13: +
A14: работник 147 | B14: Крепильщик | C14: ОБЩЕСТВО С ОГРАНИЧЕННОЙ ОТВЕТСТВЕННОСТЬЮ "АМУР ЗОЛОТО" | D14: 2708001686 | E14: ООО "Амур Золото" | F14: 2708001686 | G14: Успешно | J14: Пользовательский интерфейс | K14: 8 | M14: + | X14: + | Y14: +
A15: работник 746 | B15: Начальник по рудному направлению | C15: ОБЩЕСТВО С ОГРАНИЧЕННОЙ ОТВЕТСТВЕННОСТЬЮ "АМУР ЗОЛОТО" | D15: 2708001686 | E15: ООО "Амур Золото" | F15: 2708001686 | G15: Успешно | J15: Пользовательский интерфейс | K15: 3 | L15: + | M15: + | Y15: +
A16: работник 341 | B16: Электрогазосварщик | C16: ОБЩЕСТВО С ОГРАНИЧЕННОЙ ОТВЕТСТВЕННОСТЬЮ "АМУР ЗОЛОТО" | D16: 2708001686 | E16: ООО "Амур Золото" | F16: 2708001686 | G16: Успешно | J16: Пользовательский интерфейс | K16: 3 | M16: + | X16: + | Y16: +
A17: работник 507 | B17: Электрогазосварщик (занятый на резке и ручной сварке) | C17: ОБЩЕСТВО С ОГРАНИЧЕННОЙ ОТВЕТСТВЕННОСТЬЮ "АМУР ЗОЛОТО" | D17: 2708001686 | E17: ООО "Амур Золото" | F17: 2708001686 | G17: Успешно | J17: Пользовательский интерфейс | K17: 12 | M17: + | N17: + | O17: + | P17: + | Q17: + | R17: + | S17: + | X17: + | Y17: +
A18: работник 352 | B18: Подсобный рабочий | C18: ОБЩЕСТВО С ОГРАНИЧЕННОЙ ОТВЕТСТВЕННОСТЬЮ "АМУР ЗОЛОТО" | D18: 2708001686 | E18: ООО "Амур Золото" | F18: 2708001686 | G18: Успешно | J18: Пользовательский интерфейс | K18: 3 | M18: + | X18: + | Y18: +
A19: работник 77 | B19: Плотник | C19: ОБЩЕСТВО С ОГРАНИЧЕННОЙ ОТВЕТСТВЕННОСТЬЮ "АМУР ЗОЛОТО" | D19: 2708001686 | E19: ООО "Амур Золото" | F19: 2708001686 | G19: Успешно | J19: Пользовательский интерфейс | K19: 6 | M19: + | N19: + | U19: + | V19: + | X19: + | Y19: +
A20: работник 747 | B20: Водитель автомобиля (с правом управления КМУ) | C20: ОБЩЕСТВО С ОГРАНИЧЕННОЙ ОТВЕТСТВЕННОСТЬЮ "АМУР ЗОЛОТО" | D20: 2708001686 | E20: ООО "Амур Золото" | F20: 2708001686 | G20: Успешно | J20: Пользовательский интерфейс | K20: 2 | M20: + | Y20: +
A21: работник 48 | B21: Машинист ДВС | C21: ОБЩЕСТВО С ОГРАНИЧЕННОЙ ОТВЕТСТВЕННОСТЬЮ "АМУР ЗОЛОТО" | D21: 2708001686 | E21: ООО "Амур Золото" | F21: 2708001686 | G21: Успешно | J21: Пользовательский интерфейс | K21: 3 | M21: + | X21: + | Y21: +
A22: работник 351 | B22: Стропальщик (с исполнением обязанностей грузчика) / Кладовщик | C22: ОБЩЕСТВО С ОГРАНИЧЕННОЙ ОТВЕТСТВЕННОСТЬЮ "АМУР ЗОЛОТО" | D22: 2708001686 | E22: ООО "Амур Золото" | F22: 2708001686 | G22: Успешно | J22: Пользовательский интерфейс | K22: 5 | M22: + | X22: + | Y22: +
A23: работник 524 | B23: Машинист мельниц / Машинист конвейера | C23: ОБЩЕСТВО С ОГРАНИЧЕННОЙ ОТВЕТСТВЕННОСТЬЮ "АМУР ЗОЛОТО" | D23: 2708001686 | E23: ООО "Амур Золото" | F23: 2708001686 | G23: Успешно | J23: Пользовательский интерфейс | K23: 5 | M23: + | X23: + | Y23: +
A24: работник 409 | B24: Водитель автомобиля (занятый на транспортировании горной массы в технологическом процессе) | C24: ОБЩЕСТВО С ОГРАНИЧЕННОЙ ОТВЕТСТВЕННОСТЬЮ "АМУР ЗОЛОТО" | D24: 2708001686 | E24: ООО "Амур Золото" | F24: 2708001686 | G24: Успешно | J24: Пользовательский интерфейс | K24: 2 | M24: + | Y24: +
A25: работник 76 | B25: Монтажник по монтажу стальных и железобетонных конструкций / Монтажник ж/б и м/к | C25: ОБЩЕСТВО С ОГРАНИЧЕННОЙ ОТВЕТСТВЕННОСТЬЮ "АМУР ЗОЛОТО" | D25: 2708001686 | E25: ООО "Амур Золото" | F25: 2708001686 | G25: Успешно | J25: Пользовательский интерфейс | K25: 10 | M25: + | N25: + | U25: + | V25: + | X25: + | Y25: +
A26: работник 424 | B26: Аппаратчик-гидрометаллург / Фильтровальщик | C26: ОБЩЕСТВО С ОГРАНИЧЕННОЙ ОТВЕТСТВЕННОСТЬЮ "АМУР ЗОЛОТО" | D26: 2708001686 | E26: ООО "Амур Золото" | F26: 2708001686 | G26: Успешно | J26: Пользовательский интерфейс | K26: 8 | M26: + | X26: + | Y26: +
A27: работник 75 | B27: Плотник | C27: ОБЩЕСТВО С ОГРАНИЧЕННОЙ ОТВЕТСТВЕННОСТЬЮ "АМУР ЗОЛОТО" | D27: 2708001686 | E27: ООО "Амур Золото" | F27: 2708001686 | G27: Успешно | J27: Пользовательский интерфейс | K27: 10 | M27: + | N27: + | U27: + | V27: + | X27: + | Y27: +
A28: работник 62 | B28: Машинист ДВС с обязанностями компрессорщик / Машинист двигателей внутреннего сгорания (с исполнением обязанностей машиниста компрессорных установок) | C28: ОБЩЕСТВО С ОГРАНИЧЕННОЙ ОТВЕТСТВЕННОСТЬЮ "АМУР ЗОЛОТО" | D28: 2708001686 | E28: ООО "Амур Золото" | F28: 2708001686 | G28: Успешно | J28: Пользовательский интерфейс | K28: 6 | M28: + | X28: + | Y28: +
A29: работник 104 | B29: Повар | C29: ОБЩЕСТВО С ОГРАНИЧЕННОЙ ОТВЕТСТВЕННОСТЬЮ "АМУР ЗОЛОТО" | D29: 2708001686 | E29: ООО "Амур Золото" | F29: 2708001686 | G29: Успешно | J29: Пользовательский интерфейс | K29: 3 | M29: + | X29: + | Y29: +
A30: работник 305 | B30: Электромонтер по ремонту и обслуживанию электрооборудованию / Электромонтер / Электромонтер по ремонту и обслуживанию электрооборудования | C30: ОБЩЕСТВО С ОГРАНИЧЕННОЙ ОТВЕТСТВЕННОСТЬЮ "АМУР ЗОЛОТО" | D30: 2708001686 | E30: ООО "Амур Золото" | F30: 2708001686 | G30: Успешно | J30: Пользовательский интерфейс | K30: 10 | M30: + | N30: + | O30: + | P30: + | Q30: + | R30: + | S30: + | T30: + | Y30: +
A31: работник 249 | B31: Бункеровщик | C31: ОБЩЕСТВО С ОГРАНИЧЕННОЙ ОТВЕТСТВЕННОСТЬЮ "АМУР ЗОЛОТО" | D31: 2708001686 | E31: ООО "Амур Золото" | F31: 2708001686 | G31: Успешно | J31: Пользовательский интерфейс | K31: 3 | M31: + | X31: + | Y31: +
A32: работник 16 | B32: Машинист буровой установки (НКР) | C32: ОБЩЕСТВО С ОГРАНИЧЕННОЙ ОТВЕТСТВЕННОСТЬЮ "АМУР ЗОЛОТО" | D32: 2708001686 | E32: ООО "Амур Золото" | F32: 2708001686 | G32: Успешно | J32: Пользовательский интерфейс | K32: 3 | M32: + | X32: + | Y32: +
A33: работник 135 | B33: Горнорабочий | C33: ОБЩЕСТВО С ОГРАНИЧЕННОЙ ОТВЕТСТВЕННОСТЬЮ "АМУР ЗОЛОТО" | D33: 2708001686 | E33: ООО "Амур Золото" | F33: 2708001686 | G33: Успешно | J33: Пользовательский интерфейс | K33: 3 | M33: + | X33: + | Y33: +
A34: работник 899 | B34: Водитель автомобиля (занятый на транспортировании горной массы в технологическом процессе) | C34: ОБЩЕСТВО С ОГРАНИЧЕННОЙ ОТВЕТСТВЕННОСТЬЮ "АМУР ЗОЛОТО" | D34: 2708001686 | E34: ООО "Амур Золото" | F34: 2708001686 | G34: Успешно | J34: Пользовательский интерфейс | K34: 3 | M34: + | X34: + | Y34: +
A35: работник 672 | B35: Горнорабочий на маркшейдерских работах | C35: ОБЩЕСТВО С ОГРАНИЧЕННОЙ ОТВЕТСТВЕННОСТЬЮ "АМУР ЗОЛОТО" | D35: 2708001686 | E35: ООО "Амур Золото" | F35: 2708001686 | G35: Успешно | J35: Пользовательский интерфейс | K35: 5 | M35: + | X35: + | Y35: +
A36: работник 5 | B36: Механик по ремонту самоходного транспорта | C36: ООО "Амур золото". Подразделение: горно-обогатительный комплекс "Юбилейный" | D36: 2708001686 | E36: Автономная некоммерческая организация дополнительного профессионального образования и сертификации "Перспектива" | F36: 2722126782 | G36: Успешно | J36: Пользовательский интерфейс | K36: 4 | L36: + | M36: + | X36: + | Y36: +
A37: работник 655 | B37: Слесарь по ремонту автомобилей / Слесарь по ремонту автомобилей и тяжелой техники | C37: ОБЩЕСТВО С ОГРАНИЧЕННОЙ ОТВЕТСТВЕННОСТЬЮ "АМУР ЗОЛОТО" | D37: 2708001686 | E37: ООО "Амур Золото" | F37: 2708001686 | G37: Успешно | J37: Пользовательский интерфейс | K37: 5 | M37: + | X37: + | Y37: +
A38: работник 53 | B38: Машинист ДВС | C38: ОБЩЕСТВО С ОГРАНИЧЕННОЙ ОТВЕТСТВЕННОСТЬЮ "АМУР ЗОЛОТО" | D38: 2708001686 | E38: ООО "Амур Золото" | F38: 2708001686 | G38: Успешно | J38: Пользовательский интерфейс | K38: 3 | M38: + | X38: + | Y38: +
A39: работник 354 | B39: Водитель автомобиля (занятый на транспортировании горной массы в технологическом процессе) | C39: ОБЩЕСТВО С ОГРАНИЧЕННОЙ ОТВЕТСТВЕННОСТЬЮ "АМУР ЗОЛОТО" | D39: 2708001686 | E39: ООО "Амур Золото" | F39: 2708001686 | G39: Успешно | J39: Пользовательский интерфейс | K39: 5 | M39: + | X39: + | Y39: +
A40: работник 200 | B40: Водитель автомобиля для перевозки взрывчатых материалов | C40: ОБЩЕСТВО С ОГРАНИЧЕННОЙ ОТВЕТСТВЕННОСТЬЮ "АМУР ЗОЛОТО" | D40: 2708001686 | E40: ООО "Амур Золото" | F40: 2708001686 | G40: Успешно | J40: Пользовательский интерфейс | K40: 3 | M40: + | X40: + | Y40: +
...

Sheet Профессии
A1: В ячейке верхней таблицы — число работников, которые прошли программу, без повторных обучений. Синим выделены профессии и программы, где обучение есть не у всех работников. Жёлтым во второй таблице выделен потенциальный недостаток только по программам 46в. По первой помощи и СИЗ во второй таблице стоит разница с числом работников, и только если программа уже кому-то назначена.
A2: Профессия | B2: Исходные формулировки | C2: Работников | D2: Записей | E2: 46а. Общие вопросы охраны труда | F2: 46б. Безопасные методы при вредных и опасных факторах | G2: 46в. Работы на высоте | H2: 46в. Огневые работы | I2: 46в. Работы в ОЗП | J2: 46в. Подъемные сооружения | K2: 46в. Сосуды под давлением | L2: 46в. Технологическое оборудование | M2: 46в. Электроустановки | N2: 46в. Строительные работы | O2: 46в. Ремонт, монтаж и демонтаж зданий | P2: 46в. Земляные работы | Q2: Первая помощь пострадавшим | R2: Применение СИЗ
A3: Аппаратчик воздухоразделения | C3: 1 | D3: 4 | F3: 1 | R3: 1
A4: Аппаратчик сгустителей | B4: Аппаратчик сгустителей | Аппаратчик-сгустителей | C4: 8 | D4: 26 | F4: 5 | G4: 5 | I4: 5 | Q4: 4 | R4: 5
A5: Аппаратчик-гидрометаллург | B5: Аппаратчик-гидрометаллург | Аппаратчик-гидрометалург | аппаратчик-гидрометаллург | C5: 30 | D5: 84 | F5: 30 | Q5: 14 | R5: 30
A6: Бетонщик | C6: 3 | D6: 6 | F6: 3 | R6: 3
A7: Бункеровщик | C7: 17 | D7: 51 | F7: 17 | G7: 1 | I7: 1 | Q7: 10 | R7: 17
A8: Вальщик леса | C8: 2 | D8: 4 | F8: 2 | R8: 2
A9: Ведущий инженер ППР | C9: 1 | D9: 3 | E9: 1 | Q9: 1 | R9: 1
A10: Ведущий инженер-геодезист | C10: 2 | D10: 4 | F10: 2 | R10: 2
A11: Весовщик | C11: 12 | D11: 28 | F11: 12 | Q11: 4 | R11: 12
A12: Водитель автомобиля (занятый на транспортировании горной массы в технологическом процессе) | B12: Водитель автомобиля (занятый на транспортировании горной массы в технологическом процессе) | Водитель автомобиля(занятый на траспортировании горной массы в технологическом процессе) | C12: 50 | D12: 161 | F12: 50 | Q12: 40 | R12: 50
A13: Водитель автомобиля (категория Д) | B13: Водитель автомобиля (категория D) | Водитель автомобиля (категория Д) | C13: 19 | D13: 65 | F13: 19 | Q13: 15 | R13: 19
A14: Водитель автомобиля (категория С) | B14: Водитель автомобиля (категория С) | Водитель автомобиля кат. С | C14: 7 | D14: 20 | F14: 7 | Q14: 4 | R14: 7
A15: Водитель автомобиля (с правом управления КМУ) | C15: 2 | D15: 4 | F15: 2 | R15: 2
A16: Водитель автомобиля (топливозаправщик) | C16: 5 | D16: 15 | F16: 5 | Q16: 5 | R16: 5
A17: Водитель автомобиля для перевозки взрывчатых материалов | C17: 4 | D17: 12 | F17: 4 | Q17: 4 | R17: 4
A18: Водитель погрузчика | C18: 28 | D18: 90 | F18: 28 | Q18: 22 | R18: 28
A19: Геолог | C19: 2 | D19: 4 | Q19: 2 | R19: 2
A20: Геолог по рудоконтролю | C20: 1 | D20: 3 | F20: 1 | Q20: 1 | R20: 1
A21: Главный технолог | C21: 1 | D21: 4 | E21: 1 | F21: 1 | Q21: 1 | R21: 1
A22: Главный энергетик | C22: 1 | D22: 4 | E22: 1 | F22: 1 | Q22: 1 | R22: 1
A23: Горничная | C23: 2 | D23: 4 | F23: 2 | R23: 2
A24: Горнорабочий | C24: 6 | D24: 16 | F24: 6 | Q24: 4 | R24: 6
A25: Горнорабочий на геологических работах | C25: 6 | D25: 17 | F25: 6 | Q25: 3 | R25: 6
A26: Горнорабочий на маркшейдерских работах | B26: Горнорабочий на маркшейдерских работах | Горнорабочиий на маркшейдерских работах | C26: 9 | D26: 26 | F26: 9 | P26: 2 | Q26: 2 | R26: 9
A27: Горный диспетчер | C27: 6 | D27: 27 | E27: 1 | F27: 6 | Q27: 4 | R27: 6
A28: Горный мастер | B28: Мастер горный | Горный мастер | C28: 3 | D28: 7 | F28: 3 | Q28: 1 | R28: 3
A29: Грузчик | C29: 4 | D29: 14 | F29: 4 | Q29: 2 | R29: 4
A30: Делопроизводитель | C30: 1 | D30: 3 | E30: 1 | Q30: 1 | R30: 1
A31: Директор | C31: 1 | D31: 4 | E31: 1 | F31: 1 | Q31: 1 | R31: 1
A32: Дробильщик | B32: Дробильщик | Дробильщики | дробильщик | C32: 34 | D32: 140 | F32: 34 | Q32: 28 | R32: 34
A33: Заведующий складом аварийно химически опасных веществ | C33: 1 | D33: 2 | F33: 1 | R33: 1
A34: Заместитель главного механика | C34: 1 | D34: 2 | F34: 1 | R34: 1
A35: Заместитель директора горно-обогатительного комплекса по производству | C35: 1 | D35: 4 | E35: 1 | F35: 1 | Q35: 1 | R35: 1
A36: Заместитель начальника золотоизвлекательной фабрики | C36: 1 | D36: 4 | E36: 1 | F36: 1 | Q36: 1 | R36: 1
A37: Заместитель начальника пылевентиляционной службы | C37: 1 | D37: 2 | F37: 1 | R37: 1
A38: Заместитель начальника участка | C38: 1 | D38: 1 | H38: 1
A39: Заместитель начальника участка по буровзрывным работам | C39: 1 | D39: 4 | E39: 1 | F39: 1 | Q39: 1 | R39: 1
A40: Инженер по планированию | C40: 1 | D40: 3 | F40: 1 | Q40: 1 | R40: 1
...

Sheet Недостаток и избыток обучения
A1: Недостаток обучения
A2: Пересечение профессий и программ. Число — сколько работников профессии не прошли программу. Если этот же недостаток уже был и на вкладке «Сводная», и на вкладке «Профессии», он учтён один раз. 46а и 46б: программа уже назначена части работников профессии. Жёлтые числа по 46в — потенциальный недостаток: разница с максимумом строки только у программ, где обучение уже было. Первая помощь собрана из обеих вкладок: и те, кому она нужна по пункту 33 постановления 2464, но записи нет, и те профессии, где её прошла только часть работников. СИЗ собран так же: и высота или замкнутое пространство без СИЗ, и профессии, где СИЗ прошла только часть работников. Строка «Итого» — сумма по профессиям, столбец «Итого» — сумма по программам.
A3: Профессия | B3: Работников | C3: 46а | D3: 46б | E3: Высота | F3: Огневые | G3: ОЗП | H3: Подъемные сооружения | I3: Сосуды | J3: Оборудование | K3: Электроустановки | L3: Стройка | M3: Здания | N3: Земля | O3: Первая помощь | P3: СИЗ | Q3: Итого
A4: Электрогазосварщик | B4: 35 | D4: 4 | E4: 11 | G4: 13 | H4: 14 | I4: 14 | J4: 15 | L4: 21 | M4: 22 | O4: 13 | P4: 4 | Q4: 131
A5: Слесарь-ремонтник | B5: 12 | D5: 9 | O5: 11 | P5: 9 | Q5: 29
A6: Электромонтер по ремонту и обслуживанию электрооборудования | B6: 17 | F6: 3 | G6: 3 | H6: 3 | I6: 3 | J6: 3 | O6: 11 | Q6: 26
A7: Аппаратчик-гидрометаллург | B7: 30 | O7: 16 | Q7: 16
A8: Фильтровальщик | B8: 41 | O8: 16 | Q8: 16
A9: Повар | B9: 31 | O9: 15 | Q9: 15
A10: Помощник машиниста самоходной буровой установки (с исполнением обязанностей пробоотборщика) (Очистное) | B10: 15 | O10: 13 | Q10: 13
A11: Электромонтер | B11: 6 | D11: 4 | O11: 5 | P11: 4 | Q11: 13
A12: Проходчик (с исполнением обязанностей взрывника) | B12: 30 | D12: 3 | O12: 6 | P12: 3 | Q12: 12
A13: Аппаратчик сгустителей | B13: 8 | D13: 3 | O13: 4 | P13: 3 | Q13: 10
A14: Водитель автомобиля (занятый на транспортировании горной массы в технологическом процессе) | B14: 50 | O14: 10 | Q14: 10
A15: Машинист бульдозера | B15: 24 | O15: 9 | Q15: 9
A16: Весовщик | B16: 12 | O16: 8 | Q16: 8
A17: Машинист погрузочно-доставочной машины (занятый на транспортировании горной массы в технологическом процессе) | B17: 29 | O17: 8 | Q17: 8
A18: Подсобный рабочий | B18: 28 | O18: 8 | Q18: 8
A19: Растворщик реагентов | B19: 15 | O19: 8 | Q19: 8
A20: Бункеровщик | B20: 17 | O20: 7 | Q20: 7
A21: Горнорабочий на маркшейдерских работах | B21: 9 | O21: 7 | Q21: 7
A22: Горный диспетчер | B22: 6 | C22: 5 | O22: 2 | Q22: 7
A23: Кухонный рабочий | B23: 26 | O23: 7 | Q23: 7
A24: Плотник | B24: 14 | O24: 7 | Q24: 7
A25: Слесарь-ремонтник (по ремонту обогатительного оборудования) | B25: 17 | O25: 7 | Q25: 7
A26: Водитель погрузчика | B26: 28 | O26: 6 | Q26: 6
A27: Дробильщик | B27: 34 | O27: 6 | Q27: 6
A28: Контролер | B28: 6 | O28: 6 | Q28: 6
A29: Машинист крана автомобильного | B29: 8 | D29: 2 | O29: 2 | P29: 2 | Q29: 6
A30: Машинист самоходной буровой установки | B30: 21 | O30: 6 | Q30: 6
A31: Машинист самоходной буровой установки (Проходка) | B31: 8 | O31: 6 | Q31: 6
A32: Монтажник по монтажу стальных и железобетонных конструкций | B32: 7 | O32: 6 | Q32: 6
A33: Пробоотборщик | B33: 18 | O33: 6 | Q33: 6
A34: Машинист двигателей внутреннего сгорания | B34: 18 | O34: 5 | Q34: 5
A35: Машинист подземных самоходных машин | B35: 7 | O35: 5 | Q35: 5
A36: Водитель автомобиля (категория Д) | B36: 19 | O36: 4 | Q36: 4
A37: Машинист буровой установки | B37: 4 | O37: 4 | Q37: 4
A38: Машинист насосных установок | B38: 11 | O38: 4 | Q38: 4
A39: Оператор дизельных котлов | B39: 14 | O39: 4 | Q39: 4
A40: Помощник машиниста буровой установки | B40: 4 | O40: 4 | Q40: 4
...

Sheet Повторное обучение и просрочка
A1: Работники, которые хотя бы одну программу проходили больше одного раза. В ячейке программы — сколько раз она пройдена. Жёлтым отмечен повтор.
A2: FIO | B2: Профессия | C2: Должность в реестре | D2: Наименование работодателя | E2: ИНН работодателя | F2: Наименование организации проводившей обучение | G2: ИНН организации проводившей обучение | H2: Номера в реестре | I2: Id пакета | J2: Номера протоколов | K2: Даты проверки знаний | L2: Результат | M2: Источник отправки | N2: Всего записей | O2: Программ с повтором | P2: 46а. Общие вопросы охраны труда | Q2: 46б. Безопасные методы при вредных и опасных факторах | R2: 46в. Работы на высоте | S2: 46в. Огневые работы | T2: 46в. Работы в ОЗП | U2: 46в. Подъемные сооружения | V2: 46в. Сосуды под давлением | W2: 46в. Технологическое оборудование | X2: 46в. Электроустановки | Y2: 46в. Строительные работы | Z2: 46в. Ремонт, монтаж и демонтаж зданий | AA2: 46в. Земляные работы | AB2: Первая помощь пострадавшим | AC2: Применение СИЗ
A3: работник 406 | B3: Водитель автомобиля (категория С) | C3: Водитель автомобиля кат. С | Водитель автомобиля (категория С) | D3: ОБЩЕСТВО С ОГРАНИЧЕННОЙ ОТВЕТСТВЕННОСТЬЮ "АМУР ЗОЛОТО" | E3: 2708001686 | F3: ООО "Амур Золото" | G3: 2708001686 | H3: 82311967; 82311968; 222717230; 222717231; 222717232 | I3: 6330469; 15953442 | J3: ОТ №ЮГОК АТЦ 24-07; ЮГОК АТЦ 26-25 | K3: 08.09.2024; 19.08.2026 | L3: Успешно | M3: Пользовательский интерфейс | N3: 5 | O3: 2 | Q3: 2 | AB3: 1 | AC3: 2
A4: работник 146 | B4: Проходчик (с исполнением обязанностей взрывника) | C4: Проходчик (с исполнением обязанностей взрывника) | D4: ОБЩЕСТВО С ОГРАНИЧЕННОЙ ОТВЕТСТВЕННОСТЬЮ "АМУР ЗОЛОТО" | E4: 2708001686 | F4: ООО "Амур Золото" | G4: 2708001686 | H4: 37117737; 37117738; 37117739; 87544924; 87544925 | I4: 2978778; 6719954 | J4: ОТ № ЮГОК ПГУ 24-01; ОТ № ЮГОК ПГУ 24-23 | K4: 19.01.2024; 12.11.2024 | L4: Успешно | M4: Пользовательский интерфейс | N4: 5 | O4: 2 | Q4: 2 | AB4: 1 | AC4: 2
A5: работник 606 | B5: Кухонный рабочий | Лаборант химического анализа | C5: Кухонный рабочий | Лаборант химического анализа | D5: ОБЩЕСТВО С ОГРАНИЧЕННОЙ ОТВЕТСТВЕННОСТЬЮ "АМУР ЗОЛОТО" | E5: 2708001686 | F5: ООО "Амур Золото" | G5: 2708001686 | H5: 148627023; 148627024; 223283056; 223283057; 223283058 | I5: 11125717; 15995643 | J5: ОТ № ЮГОК УОП 25-10; ЮГОК ПАЛ 26-12 | K5: 25.09.2025; 09.09.2026 | L5: Успешно | M5: Пользовательский интерфейс | N5: 5 | O5: 2 | Q5: 2 | AB5: 1 | AC5: 2
A6: работник 32 | B6: Электромонтер | Электромонтер по ремонту и обслуживанию электрооборудования | Проходчик (с исполнением обязанностей взрывника) | C6: Электромантер | Электромонтер по ремонту и обслуживанию электрооборудования | Электромонтер по ремонту и обслуживанию электрооборудованию | Проходчик (с исполнением обязанностей взрывника) | D6: ОБЩЕСТВО С ОГРАНИЧЕННОЙ ОТВЕТСТВЕННОСТЬЮ "АМУР ЗОЛОТО" | E6: 2708001686 | F6: ООО "Амур Золото" | G6: 2708001686 | H6: 37117323; 37117324; 85344268; 85344269; 90580099; 96539148; 96539149; 96539150; 96539151; 96539152; 96539153; 148627008; 148627009; 200897027 | I6: 2978778; 6554154; 6934388; 7135797; 11125717; 14513218 | J6: ОТ № ЮГОК ЗИОФ 23-03; ОТ № ЮГОК ЗИОФ 24-33; ОТ № ЮГОК ЗИОФ 24-38; ОТ № ЮГОК ЗИОФ 24-42; ОТ № ЮГОК ПГУ 34-25; ЮГОК ЗИОФ 26-01 | K6: 24.11.2023; 25.10.2024; 25.11.2024; 10.12.2024; 21.09.2025; 05.06.2026 | L6: Успешно | M6: Пользовательский интерфейс | N6: 14 | O6: 4 | Q6: 3 | R6: 2 | S6: 1 | T6: 1 | U6: 1 | V6: 1 | W6: 1 | X6: 2 | AC6: 2
A7: работник 126 | B7: Дробильщик | C7: Дробильщик | Дробильщики | D7: ОБЩЕСТВО С ОГРАНИЧЕННОЙ ОТВЕТСТВЕННОСТЬЮ "АМУР ЗОЛОТО" | E7: 2708001686 | F7: ООО "Амур Золото" | G7: 2708001686 | H7: 37117643; 37117644; 37117645; 223283012; 223283013; 223283014 | I7: 2978778; 15995643 | J7: ОТ ЮГОК ЗИОФ 23-04; ЮГОК ЗИОФ 26-51 | K7: 11.12.2023; 26.08.2026 | L7: Успешно | M7: Пользовательский интерфейс | N7: 6 | O7: 3 | Q7: 2 | AB7: 2 | AC7: 2
A8: работник 78 | B8: Электрогазосварщик | Сварщик | C8: Электрогазосварщик (занятый на резке и ручной сварке) | Сварщик | Электрогазосварщик | D8: ОБЩЕСТВО С ОГРАНИЧЕННОЙ ОТВЕТСТВЕННОСТЬЮ "АМУР ЗОЛОТО" | E8: 2708001686 | F8: ООО "Амур Золото" | G8: 2708001686 | H8: 37117465; 37117466; 37117467; 37117495; 37117496; 37117497; 110446307; 110446308; 144713861; 144713862; 148626998; 148627022; 197822300; 197822301; 197822302 | I8: 2978778; 8371772; 10845617; 11125717; 14313480 | J8: ОТ № ЮГОК РСУ 23-01; ОТ № ЮГОК РСУ 23-02; ОТ № ЮГОК РСУ 25-01; ОТ № ЮГОК РСУ 25-04; ЮГОК ОКС (РСУ) 26-01 | K8: 23.11.2023; 24.11.2023; 29.01.2025; 23.08.2025; 23.05.2026 | L8: Успешно | M8: Пользовательский интерфейс | N8: 15 | O8: 2 | Q8: 5 | R8: 1 | S8: 1 | Y8: 1 | Z8: 1 | AB8: 1 | AC8: 5
A9: работник 666 | B9: Электрослесарь (слесарь) дежурный и по ремонту оборудования | C9: Электрослесарь (слесарь) дежурный и по ремонту оборудования | D9: ОБЩЕСТВО С ОГРАНИЧЕННОЙ ОТВЕТСТВЕННОСТЬЮ "АМУР ЗОЛОТО" | E9: 2708001686 | F9: ООО "Амур Золото" | G9: 2708001686 | H9: 180849754; 180849755; 214421465; 214421466; 214421467 | I9: 13246997; 15411209 | J9: ОТ № ЮГОК ПГУ 26-22; ЮГОК ПГУ 26-32 | K9: 09.03.2026; 28.07.2026 | L9: Успешно | M9: Пользовательский интерфейс | N9: 5 | O9: 2 | Q9: 2 | AB9: 1 | AC9: 2
A10: работник 147 | B10: Крепильщик | C10: Крепильщик | D10: ОБЩЕСТВО С ОГРАНИЧЕННОЙ ОТВЕТСТВЕННОСТЬЮ "АМУР ЗОЛОТО" | E10: 2708001686 | F10: ООО "Амур Золото" | G10: 2708001686 | H10: 37117740; 37117741; 37117742; 87544926; 87544927; 214421468; 214421469; 214421470 | I10: 2978778; 6719954; 15411209 | J10: ОТ № ЮГОК ПГУ 24-01; ОТ № ЮГОК ПГУ 24-23; ЮГОК ПГУ 26-33 | K10: 19.01.2024; 12.11.2024; 24.07.2026 | L10: Успешно | M10: Пользовательский интерфейс | N10: 8 | O10: 3 | Q10: 3 | AB10: 2 | AC10: 3
A11: работник 507 | B11: Электрогазосварщик | C11: Электрогазосварщик (занятый на резке и ручной сварке) | D11: ОБЩЕСТВО С ОГРАНИЧЕННОЙ ОТВЕТСТВЕННОСТЬЮ "АМУР ЗОЛОТО" | E11: 2708001686 | F11: ООО "Амур Золото" | G11: 2708001686 | H11: 96539106; 96539107; 96539108; 96539109; 96539110; 96539111; 148627004; 148627005; 214421480; 214421481; 214421482; 214421483 | I11: 7135797; 11125717; 15411209 | J11: ОТ № ЮГОК ЗИОФ 24-41; ОТ № ЮГОК ПГУ 32-25; ЮГОК ПГУ 26-34 | K11: 10.12.2024; 17.09.2025; 23.07.2026 | L11: Успешно | M11: Пользовательский интерфейс | N11: 12 | O11: 3 | Q11: 2 | R11: 1 | S11: 2 | T11: 1 | U11: 1 | V11: 1 | W11: 1 | AB11: 1 | AC11: 2
A12: работник 351 | B12: Стропальщик (с исполнением обязанностей грузчика) | Кладовщик | C12: Стропальщик (с исполнением обязанностей грузчика) | Кладовщик | D12: ОБЩЕСТВО С ОГРАНИЧЕННОЙ ОТВЕТСТВЕННОСТЬЮ "АМУР ЗОЛОТО" | E12: 2708001686 | F12: ООО "Амур Золото" | G12: 2708001686 | H12: 58069261; 58069262; 58069263; 82312010; 82312011 | I12: 4506532; 6330469 | J12: ОТ № ЮГОК СК 24-03; ОТ №ЮГОК СК 24-09 | K12: 15.04.2024; 16.09.2024 | L12: Успешно | M12: Пользовательский интерфейс | N12: 5 | O12: 2 | Q12: 2 | AB12: 1 | AC12: 2
A13: работник 524 | B13: Машинист конвейера | Машинист мельниц | C13: Машинист конвейера | Машинист мельниц | D13: ОБЩЕСТВО С ОГРАНИЧЕННОЙ ОТВЕТСТВЕННОСТЬЮ "АМУР ЗОЛОТО" | E13: 2708001686 | F13: ООО "Амур Золото" | G13: 2708001686 | H13: 110446277; 110446278; 214421229; 214421230; 214421231 | I13: 8371772; 15411209 | J13: ОТ № ЮГОК ЗИОФ 25-03; ЮГОК ЗИОФ 26-29 | K13: 01.02.2025; 29.07.2026 | L13: Успешно | M13: Пользовательский интерфейс | N13: 5 | O13: 2 | Q13: 2 | AB13: 1 | AC13: 2
A14: работник 76 | B14: Монтажник по монтажу стальных и железобетонных конструкций | C14: Монтажник по монтажу стальных и железобетонных конструкций | Монтажник ж/б и м/к | D14: ОБЩЕСТВО С ОГРАНИЧЕННОЙ ОТВЕТСТВЕННОСТЬЮ "АМУР ЗОЛОТО" | E14: 2708001686 | F14: ООО "Амур Золото" | G14: 2708001686 | H14: 37117459; 37117460; 37117461; 37117489; 37117490; 37117491; 82312006; 82312007; 197822303; 197822304 | I14: 2978778; 6330469; 14313480 | J14: ОТ № ЮГОК РСУ 23-01; ОТ № ЮГОК РСУ 23-02; ОТ №ЮГОК РСУ 24-03; ЮГОК ОКС (РСУ) 26-01 | K14: 23.11.2023; 24.11.2023; 05.10.2024; 23.05.2026 | L14: Успешно | M14: Пользовательский интерфейс | N14: 10 | O14: 2 | Q14: 3 | R14: 1 | Y14: 1 | Z14: 1 | AB14: 1 | AC14: 3
A15: работник 424 | B15: Аппаратчик-гидрометаллург | Фильтровальщик | C15: Аппаратчик-гидрометаллург | Фильтровальщик | D15: ОБЩЕСТВО С ОГРАНИЧЕННОЙ ОТВЕТСТВЕННОСТЬЮ "АМУР ЗОЛОТО" | E15: 2708001686 | F15: ООО "Амур Золото" | G15: 2708001686 | H15: 85344264; 85344265; 223282981; 223282982; 223282983; 223283023; 223283024; 223283025 | I15: 6554154; 15995643 | J15: ОТ № ЮГОК ЗИОФ 24-31; ЮГОК ЗИОФ 26-48; ЮГОК ЗИОФ 26-55 | K15: 20.10.2024; 26.08.2026; 07.09.2026 | L15: Успешно | M15: Пользовательский интерфейс | N15: 8 | O15: 3 | Q15: 3 | AB15: 2 | AC15: 3
A16: работник 75 | B16: Плотник | C16: Плотник | D16: ОБЩЕСТВО С ОГРАНИЧЕННОЙ ОТВЕТСТВЕННОСТЬЮ "АМУР ЗОЛОТО" | E16: 2708001686 | F16: ООО "Амур Золото" | G16: 2708001686 | H16: 37117456; 37117457; 37117458; 37117473; 37117487; 37117488; 131313254; 131313255; 197822305; 197822306 | I16: 2978778; 9873379; 14313480 | J16: ОТ № ЮГОК РСУ 23-01; ОТ № ЮГОК РСУ 23-02; ОТ № ЮГОК РСУ 25-03; ЮГОК ОКС (РСУ) 26-01 | K16: 23.11.2023; 24.11.2023; 27.06.2025; 23.05.2026 | L16: Успешно | M16: Пользовательский интерфейс | N16: 10 | O16: 2 | Q16: 3 | R16: 1 | Y16: 1 | Z16: 1 | AB16: 1 | AC16: 3
A17: работник 62 | B17: Машинист двигателей внутреннего сгорания (с исполнением обязанностей машиниста компрессорных установок) | C17: Машинист ДВС с обязанностями компрессорщик | Машинист двигателей внутреннего сгорания (с исполнением обязанностей машиниста компрессорных установок) | D17: ОБЩЕСТВО С ОГРАНИЧЕННОЙ ОТВЕТСТВЕННОСТЬЮ "АМУР ЗОЛОТО" | E17: 2708001686 | F17: ООО "Амур Золото" | G17: 2708001686 | H17: 37117416; 37117417; 37117419; 222717346; 222717347; 222717348 | I17: 2978778; 15953442 | J17: ОТ № ЮГОК ЭУ 23-01; ЮГОК ЭУ 26-23 | K17: 23.11.2023; 24.08.2026 | L17: Успешно | M17: Пользовательский интерфейс | N17: 6 | O17: 3 | Q17: 2 | AB17: 2 | AC17: 2
A18: работник 305 | B18: Электромонтер | Электромонтер по ремонту и обслуживанию электрооборудования | C18: Электромонтер | Электромонтер по ремонту и обслуживанию электрооборудования | Электромонтер по ремонту и обслуживанию электрооборудованию | D18: ОБЩЕСТВО С ОГРАНИЧЕННОЙ ОТВЕТСТВЕННОСТЬЮ "АМУР ЗОЛОТО" | E18: 2708001686 | F18: ООО "Амур Золото" | G18: 2708001686 | H18: 43299692; 43299693; 85344280; 85344281; 96539160; 96539161; 96539162; 96539163; 96539164; 96539165 | I18: 3474285; 6554154; 7135797 | J18: ОТ ЮГОК ЗИОФ 24-18; ОТ № ЮГОК ЗИОФ 24-33; ОТ № ЮГОК ЗИОФ 24-42 | K18: 06.03.2024; 25.10.2024; 10.12.2024 | L18: Успешно | M18: Пользовательский интерфейс | N18: 10 | O18: 1 | Q18: 1 | R18: 2 | S18: 1 | T18: 1 | U18: 1 | V18: 1 | W18: 1 | X18: 1 | AC18: 1
A19: работник 672 | B19: Горнорабочий на маркшейдерских работах | C19: Горнорабочий на маркшейдерских работах | D19: ОБЩЕСТВО С ОГРАНИЧЕННОЙ ОТВЕТСТВЕННОСТЬЮ "АМУР ЗОЛОТО" | E19: 2708001686 | F19: ООО "Амур Золото" | G19: 2708001686 | H19: 189084979; 189084980; 222717308; 222717309; 222717310 | I19: 13661981; 15953442 | J19: ОТ № ЮГОК ГМО 26-05; ЮГОК ОГМ 26-05 | K19: 06.04.2026; 25.08.2026 | L19: Успешно | M19: Пользовательский интерфейс | N19: 5 | O19: 2 | Q19: 2 | AB19: 1 | AC19: 2
A20: работник 655 | B20: Слесарь по ремонту автомобилей и тяжелой техники | Слесарь по ремонту автомобилей | C20: Слесарь по ремонту автомобилей и тяжелой техники | Слесарь по ремонту автомобилей | D20: ОБЩЕСТВО С ОГРАНИЧЕННОЙ ОТВЕТСТВЕННОСТЬЮ "АМУР ЗОЛОТО" | E20: 2708001686 | F20: ООО "Амур Золото" | G20: 2708001686 | H20: 180849729; 180849730; 222717218; 222717219; 222717220 | I20: 13246997; 15953442 | J20: ОТ № ЮГОК АТЦ 26-02; ЮГОК АТЦ 26-21 | K20: 07.03.2026; 18.08.2026 | L20: Успешно | M20: Пользовательский интерфейс | N20: 5 | O20: 2 | Q20: 2 | AB20: 1 | AC20: 2
A21: работник 354 | B21: Водитель автомобиля (занятый на транспортировании горной массы в технологическом процессе) | C21: Водитель автомобиля (занятый на транспортировании горной массы в технологическом процессе) | D21: ОБЩЕСТВО С ОГРАНИЧЕННОЙ ОТВЕТСТВЕННОСТЬЮ "АМУР ЗОЛОТО" | E21: 2708001686 | F21: ООО "Амур Золото" | G21: 2708001686 | H21: 66544953; 66544954; 66544955; 82311979; 82311980 | I21: 5129076; 6330469 | J21: ОТ № ЮГОК АТЦ 24-05; ОТ №ЮГОК АТЦ 24-13 | K21: 30.06.2024; 05.10.2024 | L21: Успешно | M21: Пользовательский интерфейс | N21: 5 | O21: 2 | Q21: 2 | AB21: 1 | AC21: 2
A22: работник 773 | B22: Слесарь-ремонтник (по ремонту горно-шахтного оборудования) | C22: Слесарь-ремонтник (по ремонту горно-шахтного оборудования) | D22: ОБЩЕСТВО С ОГРАНИЧЕННОЙ ОТВЕТСТВЕННОСТЬЮ "АМУР ЗОЛОТО" | E22: 2708001686 | F22: ООО "Амур Золото" | G22: 2708001686 | H22: 200897092; 200897093; 200897094; 200897095; 216771198; 216771199; 216771200 | I22: 14513218; 15571832 | J22: ЮГОК ПГУ 26-01; ЮГОК ПГУ 26-51 | K22: 04.06.2026; 17.08.2026 | L22: Успешно | M22: Пользовательский интерфейс | N22: 7 | O22: 3 | Q22: 2 | S22: 1 | AB22: 2 | AC22: 2
A23: работник 148 | B23: Машинист подземно-доставочной машины | Машинист погрузочно-доставочной машины (занятый на транспортировании горной массы в технологическом процессе) | C23: Машинист подземно-доставочной машины | Машинист погрузочно-доставочной машины (занятый на транспортировании горной массы в технологическом процессе) | D23: ОБЩЕСТВО С ОГРАНИЧЕННОЙ ОТВЕТСТВЕННОСТЬЮ "АМУР ЗОЛОТО" | E23: 2708001686 | F23: ООО "Амур Золото" | G23: 2708001686 | H23: 37117743; 37117744; 37117745; 87544928; 87544930 | I23: 2978778; 6719954 | J23: ОТ № ЮГОК ПГУ 24-01; ОТ № ЮГОК ПГУ 24-23 | K23: 19.01.2024; 12.11.2024 | L23: Успешно | M23: Пользовательский интерфейс | N23: 5 | O23: 2 | Q23: 2 | AB23: 1 | AC23: 2
A24: работник 504 | B24: Электрогазосварщик | C24: Электрогазосварщик | Электрогазосварщик (занятый на резке и ручной сварке) | D24: ОБЩЕСТВО С ОГРАНИЧЕННОЙ ОТВЕТСТВЕННОСТЬЮ "АМУР ЗОЛОТО" | E24: 2708001686 | F24: ООО "Амур Золото" | G24: 2708001686 | H24: 90580085; 90580086; 96539112; 96539113; 96539114; 96539115; 96539116; 96539117; 200897021; 200897022; 200897023; 214421304; 214421305; 214421306 | I24: 6934388; 7135797; 14513218; 15411209 | J24: ОТ № ЮГОК ЗИОФ 24-36; ОТ № ЮГОК ЗИОФ 24-41; ЮГОК ЗИОФ 26-01; ЮГОК ЗИОФ 26-37 | K24: 25.11.2024; 10.12.2024; 05.06.2026; 29.07.2026 | L24: Успешно | M24: Пользовательский интерфейс | N24: 14 | O24: 5 | Q24: 2 | R24: 2 | S24: 2 | T24: 2 | U24: 1 | V24: 1 | W24: 1 | AB24: 1 | AC24: 2
A25: работник 149 | B25: Машинист подземно-доставочной машины | Машинист погрузочно-доставочной машины | C25: Машинист подземно-доставочной машины | Машинист погрузочно-доставочной машины | D25: ОБЩЕСТВО С ОГРАНИЧЕННОЙ ОТВЕТСТВЕННОСТЬЮ "АМУР ЗОЛОТО" | E25: 2708001686 | F25: ООО "Амур Золото" | G25: 2708001686 | H25: 37117746; 37117747; 37117748; 87544931; 87544932; 216771143; 216771144; 216771145 | I25: 2978778; 6719954; 15571832 | J25: ОТ № ЮГОК ПГУ 24-01; ОТ № ЮГОК ПГУ 24-23; ЮГОК ПГУ 26-47 | K25: 19.01.2024; 12.11.2024; 15.08.2026 | L25: Успешно | M25: Пользовательский интерфейс | N25: 8 | O25: 3 | Q25: 3 | AB25: 2 | AC25: 3
A26: работник 150 | B26: Помощник машиниста самоходной буровой установки | Помощник машиниста самоходной буровой установки (с исполнением обязанностей пробоотборщика) (Очистное) | C26: Помощник машиниста самоходной буровой установки | Помощник машиниста самоходной буровой установки (с исполнением обязанностей пробоотборщика) (Очистное) | D26: ОБЩЕСТВО С ОГРАНИЧЕННОЙ ОТВЕТСТВЕННОСТЬЮ "АМУР ЗОЛОТО" | E26: 2708001686 | F26: ООО "Амур Золото" | G26: 2708001686 | H26: 37117749; 37117750; 37117751; 87544933; 87544934 | I26: 2978778; 6719954 | J26: ОТ № ЮГОК ПГУ 24-01; ОТ № ЮГОК ПГУ 24-23 | K26: 19.01.2024; 12.11.2024 | L26: Успешно | M26: Пользовательский интерфейс | N26: 5 | O26: 2 | Q26: 2 | AB26: 1 | AC26: 2
