Workbook

Sheet общие показатели
A2: Экономическая эффективность при использовании РискПроф, сроком 12 мес, по процессам:
A4: Количество работников, чел. | C4: =УЦ!E5
A6: № | B6: Процесс СУОТ | C6: Организация процессов без использования АС | D6: Организация процессов СУОТ с использованием АС РискПроф | E6: Экономический эффект (с учетом стоимости АС), руб.: | F6: Экономический эффект в пересчете на 1 работника
A7: 1 | B7: Обучение | C7: =УЦ!E42 | D7: =C13+D13 | E7: =C7-D7 | F7: =E7/C4
A8: 4 | B8: Всего: | C8: =C7 | D8: =SUM(D7:D7) | E8: =C8-D8 | F8: =E8/C4
C11: Стоимость РискПроф
A12: № | B12: модули | C12: Стоимость РискПроф (КП) | D12: стоимость трудозатрат при использовании АС
A13: 1 | B13: УЦ | C13: 4890000 | D13: =УЦ!G37 | F13: УЦ
A14: 3 | B14: Итого: | C14: =SUM(C13:C13) | D14: =SUM(D13:D13)
A15: 4 | B15: Всего: | C15: =C14+D14
A17: Эффект за счёт администрирования и функций, без штрафов, руб. | C17: ='Расчёт по доступам'!C64 | E17: на 1 работника | F17: =C17/C4
A19: Пересчёт по доступам СУЭК за 12 месяцев (24.09.2025–24.09.2026): 8 028 работников, доля 100%, 3,675 программы на работника, каталог из 83 программ. Строка «Обучение» включает штраф 60 × 130 000 руб. Эффект без этого штрафа — зелёное число выше и лист «Расчёт по доступам». Итог «Всего» равен строке «Обучение».

Sheet УЦ
A1: Экономическое обоснование использования АС "РискПроф-Учебный центр"
A3: Исходные данные:
A5: Количество работников, чел. | E5: ='Расчёт по доступам'!C6 | I5: Факт: работники с программой обучения за 12 мес. Было 35 000.
A6: Доля работников, подлежащих обучению (не освобожденных) | E6: ='Расчёт по доступам'!C7 | I6: Доля 100%. К фактическому потоку множитель 0,7 не применяется.
A7: Среднее количество программ обучения на 1 работника, ед. | E7: ='Расчёт по доступам'!C10 | I7: Среднее = человеко-программы / работники. Медиана за год — 4.
A8: Общее количество программ обучения у работодателя, ед. | E8: ='Расчёт по доступам'!C9 | I8: Программы каталога за расчётный год, без тестов и демо. Было 15.
A10: Средняя заработная плата специалиста, задействованного в выполнении перечисленных ниже видов работ, в мес., руб. | E10: =60000*1.302
A11: Средняя заработная плата специалиста, задействованного в выполнении перечисленных ниже видов работ, в час, руб. | E11: =E10/22/8
A13: Средний размер штрафа за несоответствия в сфере обучения, руб. | E13: 130000
A15: № п/п | B15: Вид работ | C15: Без использования АС | F15: С использованием АС
C16: Время на ед., час | D16: Стоимость, руб. | E16: Комментарий | F16: Время, час | G16: Стоимость, руб. | H16: Комментарий
A17: 1. Администрирование процесса обучения
A18: 1.1. | B18: Внесение сведений о работниках из штатного расписания в АС | C18: 0 | D18: 0 | E18: - | F18: =5/60 | G18: =F18*E11 | H18: Из расчета 5 минут на заполнение сведений о работниках в установленном шаблоне и загрузку файла в СДО
A19: 1.2. | B19: Формирование матрицы обучения | C19: =2/60*E5*E6 | D19: =C19*E11 | E19: Из расчета 2 минуты на одного работника, подлежащего обучению | F19: =30/3600*E5*E6 | G19: =F19*E11 | H19: Из расчета 30 секунд на одного работника, подлежащего обучению, с учетом алгоритмов автоматического назначения отдельных программ
A20: 1.3. | B20: Назначение учебных курсов в СДО | C20: =1/60*E5*E6*E7 | D20: =C20*E11 | E20: Из расчета 1 минута на одну человеко-программу | F20: 4 | G20: =F20*E11 | H20: Из расчета 4 часа на весь объем человеко-программ (автоматическое назначение учебных курсов)
A21: 1.4. | B21: Направление уведомлений о предстоящем обучении | C21: =1/60*E5*E6*E7 | D21: =C21*E11 | E21: Из расчета 1 минута на одну человеко-программу | F21: 4 | G21: =F21*E11 | H21: Из расчета 4 часа на весь объем человеко-программ (автоматическое направление уведомлений)
A22: 1.5. | B22: Отслеживание успеваемости работников | C22: =30/3600*E5*E6*E7 | D22: =C22*E11 | E22: Из расчета 30 секунд на одну человеко-программу | F22: 4 | G22: =F22*E11 | H22: Из расчета 4 часа на весь объем человеко-программ (автоматическое формирование отчетов об успеваемости)
A23: 1.6. | B23: Оформление протоколов проверки знания | C23: =3/60*E5*E6*E7 | D23: =C23*E11 | E23: Из расчета 3 минуты на одну человеко-программу | F23: 4 | G23: =F23*E11 | H23: Из расчета 4 часа на весь объем человеко-программ (автоматическое формирование протоколов)
A24: 1.7. | B24: Передача данных в РОЛ и внесение номера в протокол | C24: =1/60*E5*E6*E7 | D24: =C24*E11 | E24: Из расчета 1 минута на одну человеко-программу | F24: 0 | G24: 0 | H24: Передача данных в РОЛ и возвращение номера в протокол происходит автоматически при формировании протокола
A25: Итого по разделу 1 | C25: =SUM(C18:C24) | D25: =SUM(D18:D24) | E25: - | F25: =SUM(F18:F24) | G25: =SUM(G18:G24) | H25: -
A26: 2. Методическое обеспечение процесса обучения
A27: 2.1. | B27: Разработка программ обучения | C27: =4*E8 | D27: =C27*E11 | E27: Из расчета 4 часа на одну программу обучения | F27: 0 | G27: 0 | H27: Программы формируются автоматически на основании результатов СОУТ и ОПР
A28: 2.2. | B28: Актуализация программ обучения | C28: =1*2*E8 | D28: =C28*E11 | E28: Из расчета 1 час на одну программу обучения минимум дважды в год (1 марта и 1 сентября) | F28: 0 | G28: 0 | H28: Программы обновляются автоматически
A29: 2.3. | B29: Разработка учебных курсов | C29: =80*E8 | D29: =C29*E11 | E29: Из расчета 80 часов на одну программу обучения | F29: 0 | G29: 0 | H29: Готовые учебные курсы входят в состав АС
A30: 2.4. | B30: Актуализация учебных курсов | C30: =16*2*E8 | D30: =C30*E11 | E30: Из расчета 16 часов на одну программу обучения минимум дважды в год (1 марта и 1 сентября) | F30: 0 | G30: 0 | H30: Учебные курсы актуализируются на стороне Правообладателя
A31: 2.5. | B31: Разработка материалов для проверки знания | C31: =4*E8 | D31: =C31*E11 | E31: Из расчета 4 часа на одну программу обучения | F31: 0 | G31: 0 | H31: Готовые материалы для проверки знания входят в состав АС
A32: 2.6. | B32: Актуализация материалов для проверки знания | C32: =1*2*E8 | D32: =C32*E11 | E32: Из расчета 1 час на одну программу обучения минимум дважды в год (1 марта и 1 сентября) | F32: 0 | G32: 0 | H32: Материалы для проверки знания актуализируются на стороне Правообладателя
A33: Итого по разделу 2 | C33: =SUM(C27:C32) | D33: =SUM(D27:D32) | E33: - | F33: =SUM(F27:F32) | G33: =SUM(G27:G32) | H33: -
A34: 3. Штрафные санкции
A35: 3.1. | B35: Административные штрафы за несоответствия в сфере обучения (63 факта) | C35: - | D35: =E13*60 | E35: Из расчета среднего показателя недоназначения программ / просрочки обучения 10% от общего объема человеко-программ и потенциального выявления в ходе одной проверки 100 недозначенных / просроченных человеко-программ | F35: 0 | G35: 0 | H35: Риск недоназначения или несоблюдения сроков обучения при использовании АС сведен к минимуму
A36: Итого по разделу 3 | C36: =SUM(C35:C35) | D36: =SUM(D35:D35) | E36: - | F36: =SUM(F35:F35) | G36: =SUM(G35:G35) | H36: -
A37: ИТОГО | C37: =C25+C33+C36 | D37: =D25+D33+D36 | E37: - | F37: =F25+F33+F36 | G37: =G25+G33+G36 | H37: -
A39: Сравнение итоговых затрат:
A41: № п/п | B41: Способ организации процесса | C41: Расходы по видам работ, руб. | D41: Расходы на приобретение АС, руб. | E41: Итоговые расходы всего, руб. | F41: Итоговые расходы в пересчете на 1 работника, руб.
A42: 1 | B42: Организация процесса силами работодателя, без использования АС | C42: =D37 | D42: 0 | E42: =C42+D42 | F42: =E42/E5
A43: 2 | B43: Организация процесса с использованием АС | C43: =G37 | D43: ='общие показатели'!C13 | E43: =C43+D43 | F43: =E43/E5
A45: Исходные E5:E8 перезаписаны по доступам СУЭК за 12 месяцев. Подробности — лист «Расчёт по доступам».

Sheet Расчёт по доступам
A1: Экономический расчёт процесса подготовки работников по фактическим доступам СУЭК
A2: Горизонт — 12 месяцев. При автоматизированной системе компания экономит на администрировании процесса подготовки работников и на выполнении отдельных функций: те же операции занимают меньше часов специалиста, чем при организации без системы.
A4: 1. Исходные данные, которыми перезаписан лист «УЦ»
A5: Показатель | B5: Как считается | C5: Значение
A6: Количество работников, чел. | B6: Уникальные работники, которым за расчётные 12 месяцев назначена хотя бы одна программа обучения. На листе «УЦ» раньше стояло 35 000. | C6: 8028
A7: Доля работников, подлежащих обучению | B7: Равна 100%. Выгрузка — это уже назначенное обучение. Множитель 0,7 к фактическому потоку занизил бы его: освобождённых работников в файле нет. Раньше было 70%. | C7: 1
A8: Человеко-программы за 12 месяцев, ед. | B8: Уникальные доступы к программам обучения за расчётный год. Считается в разделе 2: все доступы года минус тесты, билеты, курсы подготовки и фрагменты тем. | C8: =C33
A9: Программ обучения у работодателя, ед. | B9: Уникальные наименования программ за расчётный год. 85 идентификаторов курса сведены к 83 названиям. Раньше было 15. | C9: 83
A10: Среднее число программ на 1 работника, ед. | B10: Человеко-программы / работники. Так формулы листа «УЦ» дают ровно фактический объём доступов. Медиана — 4 программы, как в прежней оценке; в расчёт взято среднее. | C10: =C8/(C6*C7)
A11: Жёлтые ячейки правятся вручную: лист «УЦ» и расчёт ниже пересчитаются. Зарплата, ставка часа, цена системы по коммерческому предложению и размер штрафа в выгрузке доступов не содержатся и оставлены как в исходном файле.
A13: Параметры исходного файла, которые выгрузка доступов не заменяет
A14: Параметр | B14: Откуда | C14: Значение
A15: Заработная плата с взносами, руб. в месяц | B15: Лист «УЦ»: 60 000 × 1,302 | C15: =УЦ!E10
A16: Ставка специалиста, руб. в час | B16: Месячная оплата / 22 рабочих дня / 8 часов | C16: =УЦ!E11
A17: Стоимость АС «РискПроф» по КП, руб. | B17: Лист «общие показатели». Цена коммерческого предложения не менялась. | C17: ='общие показатели'!C13
A18: Средний размер штрафа, руб. за один факт | B18: Лист «УЦ». Нужен только для отдельной оценки штрафов ниже. | C18: =УЦ!E13
A20: 2. Откуда взяты числа: файл «Доступы СУЭК за все время»
A21: Показатель | B21: Комментарий | C21: Значение
A22: Период всей выгрузки | B22: От первой до последней даты создания доступа, как она записана в файле. | C22: 15.09.2023 — 24.09.2026
A23: Строк в файле | B23: Каждая строка — один доступ работника к курсу. | C23: 64828
A24: Уникальных идентификаторов доступа | B24: 55 повторов одного идентификатора сняты и в истории, и в расчётном году. | C24: 64773
A25: Работников за всё время | B25: Уникальный идентификатор пользователя. Это накопленный поток за три года, а не численность одного года. | C25: 15079
A26: Расчётный год | B26: Последние 365 суток выгрузки. Модель на листе «общие показатели» — на 12 месяцев, поэтому три года не складываются в один. | C26: 24.09.2025 09:01 — 24.09.2026 09:01
A27: Уникальных доступов за расчётный год | B27: Все типы курсов, после снятия повторов идентификатора. | C27: 30688
A28: Работников с любым доступом за год | B28: Включая тех, у кого был только тест или билет и не было программы обучения. | C28: 8489
A29: Исключено: тестирование | B29: Наименование начинается с «Тестирование» или «Тестовый курс», а также промежуточные тесты. | C29: 1066
A30: Исключено: экзаменационные банки и билеты | B30: «Экзаменационные вопросы», «Вопросы для проверки знаний», билеты ПДД. | C30: 96
A31: Исключено: курсы подготовки к проверке знаний | B31: Повторяют основную программу и в логике исходной модели не дают отдельного протокола. | C31: 21
A32: Исключено: фрагменты тем | B32: Отдельные темы внутри программы, не самостоятельные программы. | C32: 3
A33: Человеко-программы обучения | B33: Доступы расчётного года минус исключённые строки. Это объём назначения, уведомлений, контроля, протоколов и реестра. | C33: =C27-(C29+C30+C31+C32)
A34: Работников с программой обучения | B34: Совпадает с ячейкой C6 — знаменатель среднего числа программ. | C34: =C6
A35: Программ в каталоге за год | B35: Совпадает с ячейкой C9. За всё время таких наименований 107, в расчётный год назначены 83. | C35: =C9
A36: Медиана программ на работника за год | B36: У половины работников не больше 4 программ. Прежняя оценка «4» совпала с медианой; объём в модели ведётся по среднему. | C36: 4
A37: Почему не 35 000 и не вся история. 35 000 × 0,7 — экспертная численность, в выгрузке её нет. За три года в системе 15 079 работников, но из года в год почти не повторяются одни и те же люди: подготовка — годовой поток. Поток последнего года — 8 028 работников и 29 502 человеко-программы. Кабинет в файле один: «Сибирская угольная энергетическая компания». Демо-модули, практические занятия в виртуальной среде и служебные курсы в расчётном году отсутствуют (они есть только в начале выгрузки).
A39: 3. Экономия по функциям процесса подготовки работников
A40: Нормативы времени — те же, что на листе «УЦ». Без системы функция выполняется на каждого работника, на каждую человеко-программу или на каждую программу каталога. С системой назначение, уведомления, контроль успеваемости и протоколы занимают 4 часа на весь объём; передача в реестр и методический контент выполняются системой. Стоимость часа — ячейка C16.
A41: № | B41: Функция | C41: Объём, ед. | D41: Что является объёмом | E41: Норматив без АС, час/ед. | F41: Часы без АС | G41: Стоимость без АС, руб. | H41: Норматив с АС | I41: Часы с АС | J41: Стоимость с АС, руб. | K41: Экономия, руб. | L41: За счёт чего возникает экономия | M41: Как часто
A42: 1.1 | B42: Внесение сведений о работниках в систему | C42: 1 | D42: Одна загрузка файла шаблона | E42: 0 | F42: =C42*E42 | G42: =F42*$C$16 | H42: =5/60 | I42: =C42*H42 | J42: =I42*$C$16 | K42: =G42-J42 | L42: Без системы этого шага нет. С системой — 5 минут на заполнение шаблона и загрузку файла. | M42: Ежегодно, только с АС
A43: 1.2 | B43: Формирование матрицы обучения | C43: =$C$6*$C$7 | D43: Работники, подлежащие обучению | E43: =2/60 | F43: =C43*E43 | G43: =F43*$C$16 | H43: =30/3600 | I43: =C43*H43 | J43: =I43*$C$16 | K43: =G43-J43 | L43: Без системы 2 минуты на работника. С системой 30 секунд: часть программ назначается алгоритмом. | M43: Ежегодно
A44: 1.3 | B44: Назначение учебных курсов | C44: =$C$8 | D44: Человеко-программы | E44: =1/60 | F44: =C44*E44 | G44: =F44*$C$16 | H44: 4 | I44: =H44 | J44: =I44*$C$16 | K44: =G44-J44 | L44: Без системы 1 минута на человеко-программу. С системой курсы назначаются автоматически, на весь объём заложено 4 часа. | M44: Ежегодно
...
